<?xml version="1.0"?>

<robot name="robocup" xmlns:xacro="http://ros.org/wiki/xacro">

    <!--<xacro:include filename="$(find robocup_description)/urdf/robocup.gazebo.xacro" />-->

    <xacro:macro name="SimpleTransmission" params="joint n">
      <transmission name="tran${n}">
        <type>transmission_interface/SimpleTransmission</type>
        <joint name="${joint}">
            <hardwareInterface>hardware_interface/PositionJointInterface</hardwareInterface>
        </joint>
        <actuator name="motor${n}">
            <hardwareInterface>hardware_interface/PositionJointInterface</hardwareInterface>
            <mechanicalReduction>1</mechanicalReduction>
        </actuator>
      </transmission>
    </xacro:macro>

    <link name="world"></link>

    <joint name="world_fixed" type="fixed">
        <origin xyz="0 0 0" rpy="0 0 0"/>
        <parent link="world"/>
        <child link="Torso"/>
    </joint>

    <link name='Torso'>
      <pose>0 0 0 0 -0 0</pose>
      <inertial>
        <pose>-0.00413 0 0.04342 0 -0 0</pose>        
        <mass value="1.04956" />
        <inertia 
          ixx="0.00506234"
          ixy="1.43116e-05"
          ixz="0.000155191"
          iyy="0.00488014"
          iyz="-2.70793e-05"
          izz="0.0016103"
        />
      </inertial>
      <collision name='Torso_collision'>
        <pose>0 0 0.01 0 -0 0</pose>        
          <geometry>
            <box size="0.1 0.1 0.2115"/>            
          </geometry>
        
      </collision>
      <visual name='Torso_visual'>
        <pose>0 0 0 0 -0 0</pose>
        <geometry>          
          <mesh filename="package://robocup_description/nao_red/meshes/V40/Torso.dae" scale="0.1 0.1 0.1"/>            
        </geometry>
      </visual>
      <gravity>1</gravity>
      <velocity_decay/>
      <self_collide>0</self_collide>
    </link>
    <link name='Neck'>
      <pose>0 0 0.1265 0 -0 0</pose>
      <inertial>
        <pose>-1e-05 0 -0.02742 0 -0 0</pose>
        <mass value="0.06442"/>        
        <inertia
          ixx="7.4993e-05"
          ixy="1.57e-09"
          ixz="-1.834e-08"
          iyy="7.6e-05"
          iyz="-5.295e-08"
          izz="5.53373e-06"
        />
      </inertial>
      <visual name='Neck_visual'>
        <pose>0 0 0 0 -0 0</pose>
        <geometry>
          <mesh filename="package://robocup_description/nao_red/meshes/V40/HeadYaw.dae" scale="0.1 0.1 0.1"/>          
        </geometry>
      </visual>
      <gravity>1</gravity>
      <velocity_decay/>
      <self_collide>0</self_collide>
    </link>
    <joint name='HeadYaw' type='revolute'>
      <child>Neck</child>
      <parent>Torso</parent>
      <axis>
        <xyz>0 0 1</xyz>
        <limit lower="-2.08567" upper="2.0867" effort="40.25" velocity="8.26797"/>        
        <dynamics>
          <damping>0.1</damping>
          <friction>0</friction>
          <spring_reference>0</spring_reference>
          <spring_stiffness>0</spring_stiffness>
        </dynamics>
        <use_parent_model_frame>1</use_parent_model_frame>
      </axis>
      <physics>
        <ode>
          <implicit_spring_damper>1</implicit_spring_damper>
          <cfm_damping>1</cfm_damping>
          <limit>
            <cfm>0</cfm>
            <erp>0.2</erp>
          </limit>
        </ode>
      </physics>
    </joint>

    <xacro:SimpleTransmission n="1" joint="HeadYaw"/>

    <link name='Head'>
      <pose>0 0 0.1265 0 -0 0</pose>
      <inertial>
        <pose>-0.00112 0 0.05258 0 -0 0</pose>        
        <mass value="0.60533"/>        
        <inertia
          ixx="0.0026313"
          ixy="8.78814e-06"
          ixz="4.09847e-05"
          iyy="0.00249112"
          iyz="-2.99579e-05"
          izz="0.000985736"
        />
      </inertial>
      <collision name='Head_collision'>
        <pose>0 0 0.058 1.57 -0 0</pose>
        <geometry>
          <cylinder length="0.14" radius="0.04"/>                 
        </geometry>
        <surface>
          <contact>
            <ode/>
          </contact>
          <friction>
            <ode>
              <mu>0.5</mu>
              <mu2>0.5</mu2>
            </ode>
          </friction>
        </surface>
      </collision>
      <visual name='Head_visual'>
        <pose>0 0 0 0 -0 0</pose>
        <geometry>
          <mesh filename="package://robocup_description/nao_red/meshes/V40/HeadPitch.dae" scale="0.1 0.1 0.1"/>          
        </geometry>
      </visual>
      <velocity_decay/>
      <gravity>1</gravity>
      <velocity_decay/>
      <self_collide>0</self_collide>
    </link>
    <joint name='HeadPitch' type='revolute'>
      <child>Head</child>
      <parent>Neck</parent>
      <axis>
        <xyz>0 1 0</xyz>
        <limit>
          <lower>-0.671952</lower>
          <upper>0.514872</upper>
          <effort>40.25</effort>
          <velocity>7.19407</velocity>
        </limit>
        <dynamics>
          <damping>0.1</damping>
          <friction>0</friction>
          <spring_reference>0</spring_reference>
          <spring_stiffness>0</spring_stiffness>
        </dynamics>
        <use_parent_model_frame>1</use_parent_model_frame>
      </axis>
      <physics>
        <ode>
          <implicit_spring_damper>1</implicit_spring_damper>
          <cfm_damping>1</cfm_damping>
          <limit>
            <cfm>0</cfm>
            <erp>0.2</erp>
          </limit>
        </ode>
      </physics>
    </joint>
    <xacro:SimpleTransmission n="2" joint="HeadPitch"/>
    <link name='LPelvis'>
      <pose>0 0.05 -0.085 0 -0 0</pose>
      <inertial>
        <pose>-0.00781 -0.01114 0.02661 0 -0 0</pose>        
        <mass value="0.06981"/>        
        <inertia
          ixx="8.15023e-05"
          ixy="-4.99449e-06"
          ixz="1.27482e-05"
          iyy="0.000101326"
          iyz="2.34547e-05"
          izz="6.26236e-05"
        />
      </inertial>
      <visual name='LPelvis_visual'>
        <pose>0 0 0 0 -0 0</pose>
        <geometry>
          <mesh filename="package://robocup_description/nao_red/meshes/V40/LHipYawPitch.dae" scale="0.1 0.1 0.1"/>          
        </geometry>
      </visual>
      <gravity>1</gravity>
      <velocity_decay/>
      <self_collide>0</self_collide>
    </link>
    <joint name='LHipYawPitch' type='revolute'>
      <child>LPelvis</child>
      <parent>Torso</parent>
      <axis>
        <xyz>0 0.707106 -0.707106</xyz>
        <limit>
          <lower>-1.14529</lower>
          <upper>0.740718</upper>
          <effort>59.5</effort>
          <velocity>4.16174</velocity>
        </limit>
        <dynamics>
          <damping>0.1</damping>
          <friction>0</friction>
          <spring_reference>0</spring_reference>
          <spring_stiffness>0</spring_stiffness>
        </dynamics>
        <use_parent_model_frame>1</use_parent_model_frame>
      </axis>
      <physics>
        <ode>
          <implicit_spring_damper>1</implicit_spring_damper>
          <cfm_damping>1</cfm_damping>
          <limit>
            <cfm>0</cfm>
            <erp>0.2</erp>
          </limit>
        </ode>
      </physics>
    </joint>
    <xacro:SimpleTransmission n="3" joint="LHipYawPitch"/>
    <link name='LHip'>
      <pose>0 0.05 -0.085 0 -0 0</pose>
      <inertial>
        <pose>-0.01549 0.00029 -0.00515 0 -0 0</pose>        
        <mass value="0.13053"/>        
        <inertia
          ixx="2.75835e-05"
          ixy="-2.233e-08"
          ixz="-4.08164e-06"
          iyy="9.82706e-05"
          iyz="-4.19e-09"
          izz="8.80997e-05"
        />
      </inertial>
      <visual name='LHip_visual'>
        <pose>0 0 0 0 -0 0</pose>
        <geometry>
          <mesh filename="package://robocup_description/nao_red/meshes/V40/LHipRoll.dae" scale="0.1 0.1 0.1"/>         
        </geometry>
      </visual>
      <gravity>1</gravity>
      <velocity_decay/>
      <self_collide>0</self_collide>
    </link>
    <joint name='LHipRoll' type='revolute'>
      <child>LHip</child>
      <parent>LPelvis</parent>
      <axis>
        <xyz>1 0 0</xyz>
        <limit>
          <lower>-0.379435</lower>
          <upper>0.79046</upper>
          <effort>59.5</effort>
          <velocity>4.16174</velocity>
        </limit>
        <dynamics>
          <damping>0.1</damping>
          <friction>0</friction>
          <spring_reference>0</spring_reference>
          <spring_stiffness>0</spring_stiffness>
        </dynamics>
        <use_parent_model_frame>1</use_parent_model_frame>
      </axis>
      <physics>
        <ode>
          <implicit_spring_damper>1</implicit_spring_damper>
          <cfm_damping>1</cfm_damping>
          <limit>
            <cfm>0</cfm>
            <erp>0.2</erp>
          </limit>
        </ode>
      </physics>
    </joint>
    <xacro:SimpleTransmission n="4" joint="LHipRoll"/>
    <link name='LThigh'>
      <pose>0 0.05 -0.085 0 -0 0</pose>
      <inertial>
        <pose>0.00138 0.00221 -0.05373 0 -0 0</pose>        
        <mass value="0.38968"/>        
        <inertia
          ixx="0.00163672"
          ixy="9.2451e-07"
          ixz="8.53067e-05"
          iyy="0.00159107"
          iyz="3.83616e-05"
          izz="0.000303743"
        />
      </inertial>
      <collision name='LThigh_collision'>
        <pose>0 0 -0.05 0 -0 0</pose>
        <geometry>
          <cylinder length="0.1" radius="0.04"/>          
        </geometry>
        <surface>
          <contact>
            <ode/>
          </contact>
          <friction>
            <ode>
              <mu>0.5</mu>
              <mu2>0.5</mu2>
            </ode>
          </friction>
        </surface>
      </collision>
      <visual name='LThigh_visual'>
        <pose>0 0 0 0 -0 0</pose>
        <geometry>
          <mesh filename="package://robocup_description/nao_red/meshes/V40/LHipPitch.dae" scale="0.1 0.1 0.1"/>          
        </geometry>
      </visual>
      <gravity>1</gravity>
      <velocity_decay/>
      <self_collide>0</self_collide>
    </link>
    <joint name='LHipPitch' type='revolute'>
      <child>LThigh</child>
      <parent>LHip</parent>
      <axis>
        <xyz>0 1 0</xyz>
        <limit>
          <lower>-1.53589</lower>
          <upper>0.48398</upper>
          <effort>59.5</effort>
          <velocity>6.40239</velocity>
        </limit>
        <dynamics>
          <damping>0.1</damping>
          <friction>0</friction>
          <spring_reference>0</spring_reference>
          <spring_stiffness>0</spring_stiffness>
        </dynamics>
        <use_parent_model_frame>1</use_parent_model_frame>
      </axis>
      <physics>
        <ode>
          <implicit_spring_damper>1</implicit_spring_damper>
          <cfm_damping>1</cfm_damping>
          <limit>
            <cfm>0</cfm>
            <erp>0.2</erp>
          </limit>
        </ode>
      </physics>
    </joint>
    <xacro:SimpleTransmission n="5" joint="LHipPitch"/>
    <link name='LTibia'>
      <pose>0 0.05 -0.185 0 -0 0</pose>
      <inertial>
        <pose>0.00453 0.00225 -0.04936 0 -0 0</pose>
        
        <mass value="0.29142"/>        
        <inertia
          ixx="0.00118208"
          ixy="6.3362e-07"
          ixz="3.6497e-05"
          iyy="0.00112865"
          iyz="3.94952e-05"
          izz="0.000193227"
        />
      </inertial>
      <collision name='LTibia_collision'>
        <pose>0 0 -0.05 0 -0 0</pose>
        <geometry>
          <cylinder length="0.1" radius="0.04"/>          
        </geometry>
        <surface>
          <contact>
            <ode/>
          </contact>
          <friction>
            <ode>
              <mu>0.5</mu>
              <mu2>0.5</mu2>
            </ode>
          </friction>
        </surface>
      </collision>
      <visual name='LTibia_visual'>
        <pose>0 0 0 0 -0 0</pose>
        <geometry>
          <mesh filename="package://robocup_description/nao_red/meshes/V40/LKneePitch.dae" scale="0.1 0.1 0.1"/>          
        </geometry>
      </visual>
      <gravity>1</gravity>
      <velocity_decay/>
      <self_collide>0</self_collide>
    </link>
    <joint name='LKneePitch' type='revolute'>
      <child>LTibia</child>
      <parent>LThigh</parent>
      <axis>
        <xyz>0 1 0</xyz>
        <limit>
          <lower>-0.0923279</lower>
          <upper>2.11255</upper>
          <effort>59.5</effort>
          <velocity>6.40239</velocity>
        </limit>
        <dynamics>
          <damping>0.1</damping>
          <friction>0</friction>
          <spring_reference>0</spring_reference>
          <spring_stiffness>0</spring_stiffness>
        </dynamics>
        <use_parent_model_frame>1</use_parent_model_frame>
      </axis>
      <physics>
        <ode>
          <implicit_spring_damper>1</implicit_spring_damper>
          <cfm_damping>1</cfm_damping>
          <limit>
            <cfm>0</cfm>
            <erp>0.2</erp>
          </limit>
        </ode>
      </physics>
    </joint>
    <xacro:SimpleTransmission n="6" joint="LKneePitch"/>
    <link name='LAnkle'>
      <pose>0 0.05 -0.2879 0 -0 0</pose>
      <inertial>
        <pose>0.00045 0.00029 0.00685 0 -0 0</pose>
        
        <mass value="0.13416"/>        
        <inertia
          ixx="3.85098e-05"
          ixy="-2.634e-08"
          ixz="3.86194e-06"
          iyy="7.42653e-05"
          iyz="1.834e-08"
          izz="5.48654e-05"
        />
      </inertial>
      <visual name='LAnkle_visual'>
        <pose>0 0 0 0 -0 0</pose>
        <geometry>
          <mesh filename="package://robocup_description/nao_red/meshes/V40/LAnklePitch.dae" scale="0.1 0.1 0.1"/>          
        </geometry>
      </visual>
      <gravity>1</gravity>
      <velocity_decay/>
      <self_collide>0</self_collide>
    </link>
    <joint name='LAnklePitch' type='revolute'>
      <child>LAnkle</child>
      <parent>LTibia</parent>
      <axis>
        <xyz>0 1 0</xyz>
        <limit>
          <lower>-1.18944</lower>
          <upper>0.922581</upper>
          <effort>59.5</effort>
          <velocity>6.40239</velocity>
        </limit>
        <dynamics>
          <damping>0.1</damping>
          <friction>0</friction>
          <spring_reference>0</spring_reference>
          <spring_stiffness>0</spring_stiffness>
        </dynamics>
        <use_parent_model_frame>1</use_parent_model_frame>
      </axis>
      <physics>
        <ode>
          <implicit_spring_damper>1</implicit_spring_damper>
          <cfm_damping>1</cfm_damping>
          <limit>
            <cfm>0</cfm>
            <erp>0.2</erp>
          </limit>
        </ode>
      </physics>
    </joint>
    <xacro:SimpleTransmission n="7" joint="LAnklePitch"/>
    <link name='LSole'>
      <pose>0 0.05 -0.2879 0 -0 0</pose>
      <inertial>
        <pose>0.02542 0.0033 -0.03239 0 -0 0</pose>
        
        <mass value="0.16184"/>        
        <inertia
          ixx="0.000269442"
          ixy="-5.69572e-06"
          ixz="0.000139379"
          iyy="0.000644343"
          iyz="1.87409e-05"
          izz="0.000525757"
        />
      </inertial>
      <collision name='LSole_collision'>
        <pose>0.02 0.005 -0.037 0 -0 0</pose>
        <geometry>
          <box size="0.16 0.085 0.015"/>              
        </geometry>
        <surface>
          <contact>
            <ode>
              <max_vel>0.1</max_vel>
              <min_depth>0.003</min_depth>
            </ode>
          </contact>
          <friction>
            <ode>
              <mu>0.5</mu>
              <mu2>0.5</mu2>
              <fdir1>1 0 0</fdir1>
            </ode>
          </friction>
        </surface>
      </collision>
      <visual name='LSole_visual'>
        <pose>0 0 0 0 -0 0</pose>
        <geometry>
          <mesh filename="package://robocup_description/nao_red/meshes/V40/LAnkleRoll.dae" scale="0.1 0.1 0.1"/>          
        </geometry>
      </visual>
      <gravity>1</gravity>
      <velocity_decay/>
      <self_collide>0</self_collide>
    </link>
    <joint name='LAnkleRoll' type='revolute'>
      <child>LSole</child>
      <parent>LAnkle</parent>
      <axis>
        <xyz>1 0 0</xyz>
        <limit>
          <lower>-0.397761</lower>
          <upper>0.768992</upper>
          <effort>59.5</effort>
          <velocity>4.16174</velocity>
        </limit>
        <dynamics>
          <damping>0.1</damping>
          <friction>0</friction>
          <spring_reference>0</spring_reference>
          <spring_stiffness>0</spring_stiffness>
        </dynamics>
        <use_parent_model_frame>1</use_parent_model_frame>
      </axis>
      <physics>
        <ode>
          <implicit_spring_damper>1</implicit_spring_damper>
          <cfm_damping>1</cfm_damping>
          <limit>
            <cfm>0</cfm>
            <erp>0.2</erp>
          </limit>
        </ode>
      </physics>
    </joint>
    <xacro:SimpleTransmission n="8" joint="LAnkleRoll"/>
    <link name='LShoulder'>
      <pose>0 0.098 0.1 0 -0 0</pose>
      <inertial>
        <pose>-0.00165 -0.02663 0.00014 0 -0 0</pose>
        
        <mass value="0.07504"/>        
        <inertia
          ixx="8.42843e-05"
          ixy="-2.02802e-06"
          ixz="2.338e-08"
          iyy="1.41556e-05"
          iyz="-1.972e-08"
          izz="8.64195e-05"
        />
      </inertial>
      <visual name='LShoulder_visual'>
        <pose>0 0 0 0 -0 0</pose>
        <geometry>
          <mesh filename="package://robocup_description/nao_red/meshes/V40/LShoulderPitch.dae" scale="0.1 0.1 0.1"/>          
        </geometry>
      </visual>
      <gravity>1</gravity>
      <velocity_decay/>
      <self_collide>0</self_collide>
    </link>
    <joint name='LShoulderPitch' type='revolute'>
      <child>LShoulder</child>
      <parent>Torso</parent>
      <axis>
        <xyz>0 1 0</xyz>
        <limit>
          <lower>-2.08567</lower>
          <upper>2.08567</upper>
          <effort>40.25</effort>
          <velocity>8.26797</velocity>
        </limit>
        <dynamics>
          <damping>0.1</damping>
          <friction>0</friction>
          <spring_reference>0</spring_reference>
          <spring_stiffness>0</spring_stiffness>
        </dynamics>
        <use_parent_model_frame>1</use_parent_model_frame>
      </axis>
      <physics>
        <ode>
          <implicit_spring_damper>1</implicit_spring_damper>
          <cfm_damping>1</cfm_damping>
          <limit>
            <cfm>0</cfm>
            <erp>0.2</erp>
          </limit>
        </ode>
      </physics>
    </joint>
    <xacro:SimpleTransmission n="9" joint="LShoulderPitch"/>
    <link name='LBicep'>
      <pose>0 0.098 0.1 0 -0 0</pose>
      <inertial>
        <pose>0.02455 0.00563 0.0033 0 -0 0</pose>
        
        <mass value="0.15777"/>        
        <inertia
          ixx="9.38999e-05"
          ixy="-4.71445e-05"
          ixz="-2.69947e-05"
          iyy="0.000371519"
          iyz="-2.45977e-06"
          izz="0.000341901"
        />
      </inertial>
      <collision name='LBicep_collision'>
        <pose>0.045 0 0 1.57 -0 1.8</pose>
        <geometry>
          <cylinder length="0.09" radius="0.02"/>          
        </geometry>
        <surface>
          <contact>
            <ode/>
          </contact>
          <friction>
            <ode>
              <mu>0.5</mu>
              <mu2>0.5</mu2>
            </ode>
          </friction>
        </surface>
      </collision>
      <visual name='LBicep_visual'>
        <pose>0 0 0 0 -0 0</pose>
        <geometry>
          <mesh filename="package://robocup_description/nao_red/meshes/V40/LShoulderRoll.dae" scale="0.1 0.1 0.1"/>         
        </geometry>
      </visual>
      <gravity>1</gravity>
      <velocity_decay/>
      <self_collide>0</self_collide>
    </link>
    <joint name='LShoulderRoll' type='revolute'>
      <child>LBicep</child>
      <parent>LShoulder</parent>
      <axis>
        <xyz>0 0 1</xyz>
        <limit>
          <lower>-0.314159</lower>
          <upper>1.32645</upper>
          <effort>40.25</effort>
          <velocity>7.19407</velocity>
        </limit>
        <dynamics>
          <damping>0.1</damping>
          <friction>0</friction>
          <spring_reference>0</spring_reference>
          <spring_stiffness>0</spring_stiffness>
        </dynamics>
        <use_parent_model_frame>1</use_parent_model_frame>
      </axis>
      <physics>
        <ode>
          <implicit_spring_damper>1</implicit_spring_damper>
          <cfm_damping>1</cfm_damping>
          <limit>
            <cfm>0</cfm>
            <erp>0.2</erp>
          </limit>
        </ode>
      </physics>
    </joint>
    <xacro:SimpleTransmission n="10" joint="LShoulderRoll"/>
    <link name='LElbow'>
      <pose>0.105 0.113 0.1 0 -0 0</pose>
      <inertial>
        <pose>-0.02744 0 -0.00014 0 -0 0</pose>
        
        <mass value="0.06483"/>        
        <inertia
          ixx="5.59715e-06"
          ixy="4.21e-09"
          ixz="4.319e-08"
          iyy="7.54331e-05"
          iyz="-1.84e-09"
          izz="7.64434e-05"
        />
      </inertial>
      <gravity>1</gravity>
      <velocity_decay/>
      <self_collide>0</self_collide>
    </link>
    <joint name='LElbowYaw' type='revolute'>
      <child>LElbow</child>
      <parent>LBicep</parent>
      <axis>
        <xyz>1 0 0</xyz>
        <limit>
          <lower>-2.08567</lower>
          <upper>2.08567</upper>
          <effort>40.25</effort>
          <velocity>8.26797</velocity>
        </limit>
        <dynamics>
          <damping>0.1</damping>
          <friction>0</friction>
          <spring_reference>0</spring_reference>
          <spring_stiffness>0</spring_stiffness>
        </dynamics>
        <use_parent_model_frame>1</use_parent_model_frame>
      </axis>
      <physics>
        <ode>
          <implicit_spring_damper>1</implicit_spring_damper>
          <cfm_damping>1</cfm_damping>
          <limit>
            <cfm>0</cfm>
            <erp>0.2</erp>
          </limit>
        </ode>
      </physics>
    </joint>
    <xacro:SimpleTransmission n="11" joint="LElbowYaw"/>
    <link name='LForeArm'>
      <pose>0.105 0.113 0.1 0 -0 0</pose>
      <inertial>
        <pose>0.02556 0.00281 0.00076 0 -0 0</pose>
        
        <mass value="0.07761"/>        
        <inertia
          ixx="2.53322e-05"
          ixy="-2.34271e-06"
          ixz="7.459e-08"
          iyy="8.91322e-05"
          iyz="-2.655e-08"
          izz="8.72873e-05"
        />
      </inertial>
      <collision name='LForeArm_collision'>
        <pose>0.025325 0 0 1.57 -0 1.57</pose>
        <geometry>
          <cylinder length="0.05065" radius="0.02"/>          
        </geometry>
        <surface>
          <contact>
            <ode/>
          </contact>
          <friction>
            <ode>
              <mu>0.5</mu>
              <mu2>0.5</mu2>
            </ode>
          </friction>
        </surface>
      </collision>
      <visual name='LForeArm_visual'>
        <pose>0 0 0 0 -0 0</pose>
        <geometry>
          <mesh filename="package://robocup_description/nao_red/meshes/V40/LElbowRoll.dae" scale="0.1 0.1 0.1"/>          
        </geometry>
      </visual>
      <gravity>1</gravity>
      <velocity_decay/>
      <self_collide>0</self_collide>
    </link>
    <joint name='LElbowRoll' type='revolute'>
      <child>LForeArm</child>
      <parent>LElbow</parent>
      <axis>
        <xyz>0 0 1</xyz>
        <limit>
          <lower>-1.54462</lower>
          <upper>-0.0349066</upper>
          <effort>40.25</effort>
          <velocity>7.19407</velocity>
        </limit>
        <dynamics>
          <damping>0.1</damping>
          <friction>0</friction>
          <spring_reference>0</spring_reference>
          <spring_stiffness>0</spring_stiffness>
        </dynamics>
        <use_parent_model_frame>1</use_parent_model_frame>
      </axis>
      <physics>
        <ode>
          <implicit_spring_damper>1</implicit_spring_damper>
          <cfm_damping>1</cfm_damping>
          <limit>
            <cfm>0</cfm>
            <erp>0.2</erp>
          </limit>
        </ode>
      </physics>
    </joint>
    <xacro:SimpleTransmission n="12" joint="LElbowRoll"/>
    <link name='LWrist'>
      <pose>0.16095 0.113 0.1 0 -0 0</pose>
      <inertial>
        <pose>0.03434 -0.00088 0.00308 0 -0 0</pose>
        
        <mass value="0.18533"/>        
        <inertia
          ixx="7.05493e-05"
          ixy="5.71599e-06"
          ixz="-2.24744e-05"
          iyy="0.000356062"
          iyz="3.17771e-06"
          izz="0.000351919"
        />
      </inertial>
      <collision name='LWrist_collision'>
        <pose>0.039 0 0 1.27 -0 1.57</pose>
        <geometry>
          <box size="0.06 0.04 0.058"/>          
        </geometry>
        <surface>
          <contact>
            <ode/>
          </contact>
          <friction>
            <ode>
              <mu>0.5</mu>
              <mu2>0.5</mu2>
            </ode>
          </friction>
        </surface>
      </collision>
      <visual name='LWrist_visual'>
        <pose>0 0 0 0 -0 0</pose>
        <geometry>
          <mesh filename="package://robocup_description/nao_red/meshes/V40/LWristYaw.dae" scale="0.1 0.1 0.1"/>          
        </geometry>
      </visual>
      <gravity>1</gravity>
      <velocity_decay/>
      <self_collide>0</self_collide>
    </link>
    <joint name='LWristYaw' type='revolute'>
      <child>LWrist</child>
      <parent>LForeArm</parent>
      <axis>
        <xyz>1 0 0</xyz>
        <limit>
          <lower>-1.82387</lower>
          <upper>1.82387</upper>
          <effort>40.25</effort>
          <velocity>24.6229</velocity>
        </limit>
        <dynamics>
          <damping>0.1</damping>
          <friction>0</friction>
          <spring_reference>0</spring_reference>
          <spring_stiffness>0</spring_stiffness>
        </dynamics>
        <use_parent_model_frame>1</use_parent_model_frame>
      </axis>
      <physics>
        <ode>
          <implicit_spring_damper>1</implicit_spring_damper>
          <cfm_damping>1</cfm_damping>
          <limit>
            <cfm>0</cfm>
            <erp>0.2</erp>
          </limit>
        </ode>
      </physics>
    </joint>
    <xacro:SimpleTransmission n="13" joint="LWristYaw"/>
    <link name='LFinger11'>
      <pose>0.23002 0.12457 0.09696 0 -0 0</pose>
      <inertial>
        <pose>0 0 0 0 -0 0</pose>
        
        <mass value="2e-06"/>        
        <inertia
          ixx="1e-09"
          ixy="0"
          ixz="0"
          iyy="1e-09"
          iyz="0"
          izz="1e-09"
        />
      </inertial>
      <visual name='LFinger11_visual'>
        <pose>0 0 0 0 -0 0</pose>
        <geometry>
          <mesh filename="package://robocup_description/nao_red/meshes/V40/LFinger11.dae" scale="0.1 0.1 0.1"/>          
        </geometry>
      </visual>
      <gravity>0</gravity>
      <velocity_decay/>
      <self_collide>0</self_collide>
    </link>
    <joint name='LFinger1' type='revolute'>
      <child>LFinger11</child>
      <parent>LWrist</parent>
      <axis>
        <xyz>0 1 0</xyz>
        <limit>
          <lower>0</lower>
          <upper>0.785398</upper>
          <effort>10</effort>
          <velocity>3</velocity>
        </limit>
        <dynamics>
          <damping>0.1</damping>
          <friction>0</friction>
          <spring_reference>0</spring_reference>
          <spring_stiffness>0</spring_stiffness>
        </dynamics>
        <use_parent_model_frame>1</use_parent_model_frame>
      </axis>
      <physics>
        <ode>
          <implicit_spring_damper>1</implicit_spring_damper>
          <cfm_damping>1</cfm_damping>
          <limit>
            <cfm>0</cfm>
            <erp>0.2</erp>
          </limit>
        </ode>
      </physics>
    </joint>
    <xacro:SimpleTransmission n="14" joint="LFinger1"/>
    <link name='LFinger12'>
      <pose>0.24438 0.12457 0.09696 0 -0 0</pose>
      <inertial>
        <pose>0 0 0 0 -0 0</pose>
        
        <mass value="2e-06"/>        
        <inertia
          ixx="1e-09"
          ixy="0"
          ixz="0"
          iyy="1e-09"
          iyz="0"
          izz="1e-09"
        />
      </inertial>
      <visual name='LFinger12_visual'>
        <pose>0 0 0 0 -0 0</pose>
        <geometry>
          <mesh filename="package://robocup_description/nao_red/meshes/V40/LFinger12.dae" scale="0.1 0.1 0.1"/>          
        </geometry>
      </visual>
      <gravity>0</gravity>
      <velocity_decay/>
      <self_collide>0</self_collide>
    </link>
    <joint name='LFinger1_1' type='revolute'>
      <child>LFinger12</child>
      <parent>LFinger11</parent>
      <axis>
        <xyz>0 1 0</xyz>
        <limit>
          <lower>0</lower>
          <upper>0.785398</upper>
          <effort>10</effort>
          <velocity>3</velocity>
        </limit>
        <dynamics>
          <damping>0.1</damping>
          <friction>0</friction>
          <spring_reference>0</spring_reference>
          <spring_stiffness>0</spring_stiffness>
        </dynamics>
        <use_parent_model_frame>1</use_parent_model_frame>
      </axis>
      <physics>
        <ode>
          <implicit_spring_damper>1</implicit_spring_damper>
          <cfm_damping>1</cfm_damping>
          <limit>
            <cfm>0</cfm>
            <erp>0.2</erp>
          </limit>
        </ode>
      </physics>
    </joint>
    <xacro:SimpleTransmission n="15" joint="LFinger1_1"/>
    <link name='LFinger13'>
      <pose>0.25874 0.12457 0.09696 0 -0 0</pose>
      <inertial>
        <pose>0 0 0 0 -0 0</pose>
        
        <mass value="2e-06"/>        
        <inertia
          ixx="1e-09"
          ixy="0"
          ixz="0"
          iyy="1e-09"
          iyz="0"
          izz="1e-09"
        />
      </inertial>
      <visual name='LFinger13_visual'>
        <pose>0 0 0 0 -0 0</pose>
        <geometry>
          <mesh filename="package://robocup_description/nao_red/meshes/V40/LFinger13.dae" scale="0.1 0.1 0.1"/>          
        </geometry>
      </visual>
      <gravity>0</gravity>
      <velocity_decay/>
      <self_collide>0</self_collide>
    </link>
    <joint name='LFinger1_2' type='revolute'>
      <child>LFinger13</child>
      <parent>LFinger12</parent>
      <axis>
        <xyz>0 1 0</xyz>
        <limit>
          <lower>0</lower>
          <upper>0.785398</upper>
          <effort>10</effort>
          <velocity>3</velocity>
        </limit>
        <dynamics>
          <damping>0.1</damping>
          <friction>0</friction>
          <spring_reference>0</spring_reference>
          <spring_stiffness>0</spring_stiffness>
        </dynamics>
        <use_parent_model_frame>1</use_parent_model_frame>
      </axis>
      <physics>
        <ode>
          <implicit_spring_damper>1</implicit_spring_damper>
          <cfm_damping>1</cfm_damping>
          <limit>
            <cfm>0</cfm>
            <erp>0.2</erp>
          </limit>
        </ode>
      </physics>
    </joint>
    <xacro:SimpleTransmission n="16" joint="LFinger1_2"/>
    <link name='LFinger21'>
      <pose>0.23002 0.10143 0.09696 0 -0 0</pose>
      <inertial>
        <pose>0 0 0 0 -0 0</pose>
        <mass value="2e-06"/>        
        <inertia
          ixx="1e-09"
          ixy="0"
          ixz="0"
          iyy="1e-09"
          iyz="0"
          izz="1e-09"
        />
      </inertial>
      <visual name='LFinger21_visual'>
        <pose>0 0 0 0 -0 0</pose>
        <geometry>
          <mesh filename="package://robocup_description/nao_red/meshes/V40/LFinger21.dae" scale="0.1 0.1 0.1"/>          
        </geometry>
      </visual>
      <gravity>0</gravity>
      <velocity_decay/>
      <self_collide>0</self_collide>
    </link>
    <joint name='LFinger2' type='revolute'>
      <child>LFinger21</child>
      <parent>LWrist</parent>
      <axis>
        <xyz>0 1 0</xyz>
        <limit>
          <lower>0</lower>
          <upper>0.785398</upper>
          <effort>10</effort>
          <velocity>3</velocity>
        </limit>
        <dynamics>
          <damping>0.1</damping>
          <friction>0</friction>
          <spring_reference>0</spring_reference>
          <spring_stiffness>0</spring_stiffness>
        </dynamics>
        <use_parent_model_frame>1</use_parent_model_frame>
      </axis>
      <physics>
        <ode>
          <implicit_spring_damper>1</implicit_spring_damper>
          <cfm_damping>1</cfm_damping>
          <limit>
            <cfm>0</cfm>
            <erp>0.2</erp>
          </limit>
        </ode>
      </physics>
    </joint>
    <xacro:SimpleTransmission n="17" joint="LFinger2"/>
    <link name='LFinger22'>
      <pose>0.24438 0.10143 0.09696 0 -0 0</pose>
      <inertial>
        <pose>0 0 0 0 -0 0</pose>
        <mass value="2e-06"/>        
        <inertia
          ixx="1e-09"
          ixy="0"
          ixz="0"
          iyy="1e-09"
          iyz="0"
          izz="1e-09"
        />
      </inertial>
      <visual name='LFinger22_visual'>
        <pose>0 0 0 0 -0 0</pose>
        <geometry>
          <mesh filename="package://robocup_description/nao_red/meshes/V40/LFinger22.dae" scale="0.1 0.1 0.1"/>          
        </geometry>
      </visual>
      <gravity>0</gravity>
      <velocity_decay/>
      <self_collide>0</self_collide>
    </link>
    <joint name='LFinger2_1' type='revolute'>
      <child>LFinger22</child>
      <parent>LFinger21</parent>
      <axis>
        <xyz>0 1 0</xyz>
        <limit>
          <lower>0</lower>
          <upper>0.785398</upper>
          <effort>10</effort>
          <velocity>3</velocity>
        </limit>
        <dynamics>
          <damping>0.1</damping>
          <friction>0</friction>
          <spring_reference>0</spring_reference>
          <spring_stiffness>0</spring_stiffness>
        </dynamics>
        <use_parent_model_frame>1</use_parent_model_frame>
      </axis>
      <physics>
        <ode>
          <implicit_spring_damper>1</implicit_spring_damper>
          <cfm_damping>1</cfm_damping>
          <limit>
            <cfm>0</cfm>
            <erp>0.2</erp>
          </limit>
        </ode>
      </physics>
    </joint>
    <xacro:SimpleTransmission n="18" joint="LFinger2_1"/>
    <link name='LFinger23'>
      <pose>0.25874 0.10143 0.09696 0 -0 0</pose>
      <inertial>
        <pose>0 0 0 0 -0 0</pose>
        <mass value="2e-06"/>        
        <inertia
          ixx="1e-09"
          ixy="0"
          ixz="0"
          iyy="1e-09"
          iyz="0"
          izz="1e-09"
        />
      </inertial>
      <visual name='LFinger23_visual'>
        <pose>0 0 0 0 -0 0</pose>
        <geometry>
          <mesh filename="package://robocup_description/nao_red/meshes/V40/LFinger23.dae" scale="0.1 0.1 0.1"/>          
        </geometry>
      </visual>
      <gravity>0</gravity>
      <velocity_decay/>
      <self_collide>0</self_collide>
    </link>
    <joint name='LFinger2_2' type='revolute'>
      <child>LFinger23</child>
      <parent>LFinger22</parent>
      <axis>
        <xyz>0 1 0</xyz>
        <limit>
          <lower>0</lower>
          <upper>0.785398</upper>
          <effort>10</effort>
          <velocity>3</velocity>
        </limit>
        <dynamics>
          <damping>0.1</damping>
          <friction>0</friction>
          <spring_reference>0</spring_reference>
          <spring_stiffness>0</spring_stiffness>
        </dynamics>
        <use_parent_model_frame>1</use_parent_model_frame>
      </axis>
      <physics>
        <ode>
          <implicit_spring_damper>1</implicit_spring_damper>
          <cfm_damping>1</cfm_damping>
          <limit>
            <cfm>0</cfm>
            <erp>0.2</erp>
          </limit>
        </ode>
      </physics>
    </joint>
    <xacro:SimpleTransmission n="19" joint="LFinger2_2"/>
    <link name='LGripper'>
      <pose>0.2187 0.113 0.08769 0 -0 0</pose>
      <inertial>
        <pose>0 0 0 0 -0 0</pose>
        <mass value="2e-06"/>        
        <inertia
          ixx="1.1e-09"
          ixy="0"
          ixz="0"
          iyy="1.1e-09"
          iyz="0"
          izz="1.1e-09"
        />
      </inertial>
      <gravity>0</gravity>
      <velocity_decay/>
      <self_collide>0</self_collide>
    </link>
    <joint name='LHand' type='revolute'>
      <child>LGripper</child>
      <parent>LWrist</parent>
      <axis>
        <xyz>1 0 0</xyz>
        <limit>
          <lower>0</lower>
          <upper>1</upper>
          <effort>0.177576</effort>
          <velocity>3</velocity>
        </limit>
        <dynamics>
          <damping>0.1</damping>
          <friction>0</friction>
          <spring_reference>0</spring_reference>
          <spring_stiffness>0</spring_stiffness>
        </dynamics>
        <use_parent_model_frame>1</use_parent_model_frame>
      </axis>
      <physics>
        <ode>
          <implicit_spring_damper>1</implicit_spring_damper>
          <cfm_damping>1</cfm_damping>
          <limit>
            <cfm>0</cfm>
            <erp>0.2</erp>
          </limit>
        </ode>
      </physics>
    </joint>
    <xacro:SimpleTransmission n="20" joint="LHand"/>
    <link name='LThumb1'>
      <pose>0.2099 0.113 0.07362 -3.14159 0.785398 0</pose>
      <inertial>
        <pose>0 0 0 0 -0 0</pose>
        <mass value="2e-06"/>        
        <inertia
          ixx="1e-09"
          ixy="0"
          ixz="0"
          iyy="1e-09"
          iyz="0"
          izz="1e-09"
        />
      </inertial>
      <visual name='LThumb1_visual'>
        <pose>0 0 0 0 -0 0</pose>
        <geometry>
          <mesh filename="package://robocup_description/nao_red/meshes/V40/LThumb1.dae" scale="0.1 0.1 0.1"/>          
        </geometry>
      </visual>
      <gravity>0</gravity>
      <velocity_decay/>
      <self_collide>0</self_collide>
    </link>
    <joint name='LThumb1_joint' type='revolute'>
      <child>LThumb1</child>
      <parent>LWrist</parent>
      <axis>
        <xyz>-0 -1 -0</xyz>
        <limit>
          <lower>0</lower>
          <upper>0.785398</upper>
          <effort>10</effort>
          <velocity>3</velocity>
        </limit>
        <dynamics>
          <damping>0.1</damping>
          <friction>0</friction>
          <spring_reference>0</spring_reference>
          <spring_stiffness>0</spring_stiffness>
        </dynamics>
        <use_parent_model_frame>1</use_parent_model_frame>
      </axis>
      <physics>
        <ode>
          <implicit_spring_damper>1</implicit_spring_damper>
          <cfm_damping>1</cfm_damping>
          <limit>
            <cfm>0</cfm>
            <erp>0.2</erp>
          </limit>
        </ode>
      </physics>
    </joint>
    <xacro:SimpleTransmission n="21" joint="LThumb1_joint"/>
    <link name='LThumb2'>
      <pose>0.220054 0.113 0.063466 -3.14159 0.785398 0</pose>
      <inertial>
        <pose>0 0 0 0 -0 0</pose>
        <mass value="2e-06"/>        
        <inertia
          ixx="1e-09"
          ixy="0"
          ixz="0"
          iyy="1e-09"
          iyz="0"
          izz="1e-09"
        />
      </inertial>
      <visual name='LThumb2_visual'>
        <pose>0 0 0 0 -0 0</pose>
        <geometry>
          <mesh filename="package://robocup_description/nao_red/meshes/V40/LThumb2.dae" scale="0.1 0.1 0.1"/>          
        </geometry>
      </visual>
      <gravity>0</gravity>
      <velocity_decay/>
      <self_collide>0</self_collide>
    </link>
    <joint name='LThumb1_2' type='revolute'>
      <child>LThumb2</child>
      <parent>LThumb1</parent>
      <axis>
        <xyz>-0 -1 -0</xyz>
        <limit>
          <lower>0</lower>
          <upper>0.785398</upper>
          <effort>10</effort>
          <velocity>3</velocity>
        </limit>
        <dynamics>
          <damping>0.1</damping>
          <friction>0</friction>
          <spring_reference>0</spring_reference>
          <spring_stiffness>0</spring_stiffness>
        </dynamics>
        <use_parent_model_frame>1</use_parent_model_frame>
      </axis>
      <physics>
        <ode>
          <implicit_spring_damper>1</implicit_spring_damper>
          <cfm_damping>1</cfm_damping>
          <limit>
            <cfm>0</cfm>
            <erp>0.2</erp>
          </limit>
        </ode>
      </physics>
    </joint>
    <xacro:SimpleTransmission n="22" joint="LThumb1_2"/>
    <link name='RPelvis'>
      <pose>0 -0.05 -0.085 0 -0 0</pose>
      <inertial>
        <pose>-0.00781 0.01114 0.02661 0 -0 0</pose>
        
        <mass value="0.06981"/>        
        <inertia
          ixx="8.9972e-05"
          ixy="5.00219e-06"
          ixz="1.27352e-05"
          iyy="0.000105526"
          iyz="-2.77008e-05"
          izz="6.68872e-05"
        />
      </inertial>
      <collision name='RPelvis_collision'>
        <pose>0 0 -0.05 0 -0 0</pose>
        <geometry>
          <cylinder length="0.1" radius="0.04"/>          
        </geometry>
        <surface>
          <contact>
            <ode/>
          </contact>
          <friction>
            <ode>
              <mu>0.5</mu>
              <mu2>0.5</mu2>
            </ode>
          </friction>
        </surface>
      </collision>
      <visual name='RPelvis_visual'>
        <pose>0 0 0 0 -0 0</pose>
        <geometry>
          <mesh filename="package://robocup_description/nao_red/meshes/V40/RHipYawPitch.dae" scale="0.1 0.1 0.1"/>          
        </geometry>
      </visual>
      <gravity>1</gravity>
      <velocity_decay/>
      <self_collide>0</self_collide>
    </link>
    <joint name='RHipYawPitch' type='revolute'>
      <child>RPelvis</child>
      <parent>Torso</parent>
      <axis>
        <xyz>0 0.707106 0.707106</xyz>
        <limit>
          <lower>-1.14529</lower>
          <upper>0.740718</upper>
          <effort>59.5</effort>
          <velocity>4.16174</velocity>
        </limit>
        <dynamics>
          <damping>0.1</damping>
          <friction>0</friction>
          <spring_reference>0</spring_reference>
          <spring_stiffness>0</spring_stiffness>
        </dynamics>
        <use_parent_model_frame>1</use_parent_model_frame>
      </axis>
      <physics>
        <ode>
          <implicit_spring_damper>1</implicit_spring_damper>
          <cfm_damping>1</cfm_damping>
          <limit>
            <cfm>0</cfm>
            <erp>0.2</erp>
          </limit>
        </ode>
      </physics>
    </joint>
    <xacro:SimpleTransmission n="23" joint="RHipYawPitch"/>
    <link name='RHip'>
      <pose>0 -0.05 -0.085 0 -0 0</pose>
      <inertial>
        <pose>-0.01549 -0.00029 -0.00515 0 -0 0</pose>
        
        <mass value="0.13053"/>        
        <inertia
          ixx="2.75865e-05"
          ixy="-1.919e-08"
          ixz="-4.10822e-06"
          iyy="9.827e-05"
          iyz="2.51e-09"
          izz="8.81033e-05"
        />
      </inertial>
      <visual name='RHip_visual'>
        <pose>0 0 0 0 -0 0</pose>
        <geometry>
          <mesh filename="package://robocup_description/nao_red/meshes/V40/RHipRoll.dae" scale="0.1 0.1 0.1"/>          
        </geometry>
      </visual>
      <gravity>1</gravity>
      <velocity_decay/>
      <self_collide>0</self_collide>
    </link>
    <joint name='RHipRoll' type='revolute'>
      <child>RHip</child>
      <parent>RPelvis</parent>
      <axis>
        <xyz>1 0 0</xyz>
        <limit>
          <lower>-0.79046</lower>
          <upper>0.379435</upper>
          <effort>59.5</effort>
          <velocity>4.16174</velocity>
        </limit>
        <dynamics>
          <damping>0.1</damping>
          <friction>0</friction>
          <spring_reference>0</spring_reference>
          <spring_stiffness>0</spring_stiffness>
        </dynamics>
        <use_parent_model_frame>1</use_parent_model_frame>
      </axis>
      <physics>
        <ode>
          <implicit_spring_damper>1</implicit_spring_damper>
          <cfm_damping>1</cfm_damping>
          <limit>
            <cfm>0</cfm>
            <erp>0.2</erp>
          </limit>
        </ode>
      </physics>
    </joint>
    <xacro:SimpleTransmission n="24" joint="RHipRoll"/>
    <link name='RThigh'>
      <pose>0 -0.05 -0.085 0 -0 0</pose>
      <inertial>
        <pose>0.00138 -0.00221 -0.05373 0 -0 0</pose>
        
        <mass value="0.38968"/>        
        <inertia
          ixx="0.00163748"
          ixy="-8.3954e-07"
          ixz="8.5883e-05"
          iyy="0.00159221"
          iyz="-3.91763e-05"
          izz="0.000303978"
        />
      </inertial>
      <visual name='RThigh_visual'>
        <pose>0 0 0 0 -0 0</pose>
        <geometry>
          <mesh filename="package://robocup_description/nao_red/meshes/V40/RHipPitch.dae" scale="0.1 0.1 0.1"/>          
        </geometry>
      </visual>
      <gravity>1</gravity>
      <velocity_decay/>
      <self_collide>0</self_collide>
    </link>
    <joint name='RHipPitch' type='revolute'>
      <child>RThigh</child>
      <parent>RHip</parent>
      <axis>
        <xyz>0 1 0</xyz>
        <limit>
          <lower>-1.53589</lower>
          <upper>0.48398</upper>
          <effort>59.5</effort>
          <velocity>6.40239</velocity>
        </limit>
        <dynamics>
          <damping>0.1</damping>
          <friction>0</friction>
          <spring_reference>0</spring_reference>
          <spring_stiffness>0</spring_stiffness>
        </dynamics>
        <use_parent_model_frame>1</use_parent_model_frame>
      </axis>
      <physics>
        <ode>
          <implicit_spring_damper>1</implicit_spring_damper>
          <cfm_damping>1</cfm_damping>
          <limit>
            <cfm>0</cfm>
            <erp>0.2</erp>
          </limit>
        </ode>
      </physics>
    </joint>
    <xacro:SimpleTransmission n="25" joint="RHipPitch"/>
    <link name='RTibia'>
      <pose>0 -0.05 -0.185 0 -0 0</pose>
      <inertial>
        <pose>0.00453 -0.00225 -0.04936 0 -0 0</pose>
        
        <mass value="0.29142"/>        
        <inertia
          ixx="0.00118283"
          ixy="-8.965e-07"
          ixz="2.79969e-05"
          iyy="0.00112828"
          iyz="-3.8476e-05"
          izz="0.000191453"
        />
      </inertial>
      <collision name='RTibia_collision'>
        <pose>0 0 -0.05 0 -0 0</pose>
        <geometry>
          <cylinder length="0.1" radius="0.04"/>          
        </geometry>
        <surface>
          <contact>
            <ode/>
          </contact>
          <friction>
            <ode>
              <mu>0.5</mu>
              <mu2>0.5</mu2>
            </ode>
          </friction>
        </surface>
      </collision>
      <visual name='RTibia_visual'>
        <pose>0 0 0 0 -0 0</pose>
        <geometry>
          <mesh filename="package://robocup_description/nao_red/meshes/V40/RKneePitch.dae" scale="0.1 0.1 0.1"/>          
        </geometry>
      </visual>
      <gravity>1</gravity>
      <velocity_decay/>
      <self_collide>0</self_collide>
    </link>
    <joint name='RKneePitch' type='revolute'>
      <child>RTibia</child>
      <parent>RThigh</parent>
      <axis>
        <xyz>0 1 0</xyz>
        <limit>
          <lower>-0.0923279</lower>
          <upper>2.11255</upper>
          <effort>59.5</effort>
          <velocity>6.40239</velocity>
        </limit>
        <dynamics>
          <damping>0.1</damping>
          <friction>0</friction>
          <spring_reference>0</spring_reference>
          <spring_stiffness>0</spring_stiffness>
        </dynamics>
        <use_parent_model_frame>1</use_parent_model_frame>
      </axis>
      <physics>
        <ode>
          <implicit_spring_damper>1</implicit_spring_damper>
          <cfm_damping>1</cfm_damping>
          <limit>
            <cfm>0</cfm>
            <erp>0.2</erp>
          </limit>
        </ode>
      </physics>
    </joint>
    <xacro:SimpleTransmission n="26" joint="RKneePitch"/>
    <link name='RAnkle'>
      <pose>0 -0.05 -0.2879 0 -0 0</pose>
      <inertial>
        <pose>0.00045 -0.00029 0.00685 0 -0 0</pose>
        
        <mass value="0.13416"/>        
        <inertia
          ixx="3.85081e-05"
          ixy="6.434e-08"
          ixz="3.87466e-06"
          iyy="7.43108e-05"
          iyz="-4.58e-09"
          izz="5.49131e-05"
        />
      </inertial>
      <visual name='RAnkle_visual'>
        <pose>0 0 0 0 -0 0</pose>
        <geometry>
          <mesh filename="package://robocup_description/nao_red/meshes/V40/RAnklePitch.dae" scale="0.1 0.1 0.1"/>          
        </geometry>
      </visual>
      <gravity>1</gravity>
      <velocity_decay/>
      <self_collide>0</self_collide>
    </link>
    <joint name='RAnklePitch' type='revolute'>
      <child>RAnkle</child>
      <parent>RTibia</parent>
      <axis>
        <xyz>0 1 0</xyz>
        <limit>
          <lower>-1.1863</lower>
          <upper>0.932006</upper>
          <effort>59.5</effort>
          <velocity>6.40239</velocity>
        </limit>
        <dynamics>
          <damping>0.1</damping>
          <friction>0</friction>
          <spring_reference>0</spring_reference>
          <spring_stiffness>0</spring_stiffness>
        </dynamics>
        <use_parent_model_frame>1</use_parent_model_frame>
      </axis>
      <physics>
        <ode>
          <implicit_spring_damper>1</implicit_spring_damper>
          <cfm_damping>1</cfm_damping>
          <limit>
            <cfm>0</cfm>
            <erp>0.2</erp>
          </limit>
        </ode>
      </physics>
    </joint>
    <xacro:SimpleTransmission n="27" joint="RAnklePitch"/>
    <link name='RSole'>
      <pose>0 -0.05 -0.2879 0 -0 0</pose>
      <inertial>
        <pose>0.02542 -0.0033 -0.03239 0 -0 0</pose>
        
        <mass value="0.16184"/>        
        <inertia
          ixx="0.000269302"
          ixy="5.87505e-06"
          ixz="0.000139133"
          iyy="0.000643474"
          iyz="-1.88492e-05"
          izz="0.000525035"
        />
      </inertial>
      <collision name='RSole_collision'>
        <pose>0.02 -0.005 -0.037 0 -0 0</pose>
        <geometry>
          <box size="0.16 0.085 0.015"/>          
        </geometry>
        <surface>
          <contact>
            <ode>
              <max_vel>0.1</max_vel>
              <min_depth>0.003</min_depth>
            </ode>
          </contact>
          <friction>
            <ode>
              <mu>0.5</mu>
              <mu2>0.5</mu2>
              <fdir1>1 0 0</fdir1>
            </ode>
          </friction>
        </surface>
      </collision>
      <visual name='RSole_visual'>
        <pose>0 0 0 0 -0 0</pose>
        <geometry>
          <mesh filename="package://robocup_description/nao_red/meshes/V40/RAnkleRoll.dae" scale="0.1 0.1 0.1"/>          
        </geometry>
      </visual>
      <gravity>1</gravity>
      <velocity_decay/>
      <self_collide>0</self_collide>
    </link>
    <joint name='RAnkleRoll' type='revolute'>
      <child>RSole</child>
      <parent>RAnkle</parent>
      <axis>
        <xyz>1 0 0</xyz>
        <limit>
          <lower>-0.768992</lower>
          <upper>0.397935</upper>
          <effort>59.5</effort>
          <velocity>4.16174</velocity>
        </limit>
        <dynamics>
          <damping>0.1</damping>
          <friction>0</friction>
          <spring_reference>0</spring_reference>
          <spring_stiffness>0</spring_stiffness>
        </dynamics>
        <use_parent_model_frame>1</use_parent_model_frame>
      </axis>
      <physics>
        <ode>
          <implicit_spring_damper>1</implicit_spring_damper>
          <cfm_damping>1</cfm_damping>
          <limit>
            <cfm>0</cfm>
            <erp>0.2</erp>
          </limit>
        </ode>
      </physics>
    </joint>
    <xacro:SimpleTransmission n="28" joint="RAnkleRoll"/>
    <link name='RShoulder'>
      <pose>0 -0.098 0.1 0 -0 0</pose>
      <inertial>
        <pose>-0.00165 0.02663 0.00014 0 -0 0</pose>
        
        <mass value="0.07504"/>        
        <inertia
          ixx="8.42843e-05"
          ixy="2.02802e-06"
          ixz="2.338e-08"
          iyy="1.41556e-054"
          iyz="1.972e-08"
          izz="8.64195e-05"
        />
      </inertial>
      <visual name='RShoulder_visual'>
        <pose>0 0 0 0 -0 0</pose>
        <geometry>
          <mesh filename="package://robocup_description/nao_red/meshes/V40/RShoulderPitch.dae" scale="0.1 0.1 0.1"/>          
        </geometry>
      </visual>
      <gravity>1</gravity>
      <velocity_decay/>
      <self_collide>0</self_collide>
    </link>
    <joint name='RShoulderPitch' type='revolute'>
      <child>RShoulder</child>
      <parent>Torso</parent>
      <axis>
        <xyz>0 1 0</xyz>
        <limit>
          <lower>-2.08567</lower>
          <upper>2.08567</upper>
          <effort>40.25</effort>
          <velocity>8.26797</velocity>
        </limit>
        <dynamics>
          <damping>0.1</damping>
          <friction>0</friction>
          <spring_reference>0</spring_reference>
          <spring_stiffness>0</spring_stiffness>
        </dynamics>
        <use_parent_model_frame>1</use_parent_model_frame>
      </axis>
      <physics>
        <ode>
          <implicit_spring_damper>1</implicit_spring_damper>
          <cfm_damping>1</cfm_damping>
          <limit>
            <cfm>0</cfm>
            <erp>0.2</erp>
          </limit>
        </ode>
      </physics>
    </joint>
    <xacro:SimpleTransmission n="29" joint="RShoulderPitch"/>
    <link name='RBicep'>
      <pose>0 -0.098 0.1 0 -0 0</pose>
      <inertial>
        <pose>0.02455 -0.00563 0.0033 0 -0 0</pose>
        
        <mass value="0.15777"/>        
        <inertia
          ixx="0.00011012"
          ixy="7.66913e-05"
          ixz="-2.60461e-05"
          iyy="0.000367577"
          iyz="1.20983e-05"
          izz="0.000354618"
        />
      </inertial>
      <collision name='RBicep_collision'>
        <pose>0.045 0 0 1.57 0 -1.8</pose>
        <geometry>
          <cylinder length="0.09" radius="0.02"/>          
        </geometry>
        <surface>
          <contact>
            <ode/>
          </contact>
          <friction>
            <ode>
              <mu>0.5</mu>
              <mu2>0.5</mu2>
            </ode>
          </friction>
        </surface>
      </collision>
      <visual name='RBicep_visual'>
        <pose>0 0 0 0 -0 0</pose>
        <geometry>
          <mesh filename="package://robocup_description/nao_red/meshes/V40/RShoulderRoll.dae" scale="0.1 0.1 0.1"/>          
        </geometry>
      </visual>
      <gravity>1</gravity>
      <velocity_decay/>
      <self_collide>0</self_collide>
    </link>
    <joint name='RShoulderRoll' type='revolute'>
      <child>RBicep</child>
      <parent>RShoulder</parent>
      <axis>
        <xyz>0 0 1</xyz>
        <limit>
          <lower>-1.32645</lower>
          <upper>0.314159</upper>
          <effort>40.25</effort>
          <velocity>7.19407</velocity>
        </limit>
        <dynamics>
          <damping>0.1</damping>
          <friction>0</friction>
          <spring_reference>0</spring_reference>
          <spring_stiffness>0</spring_stiffness>
        </dynamics>
        <use_parent_model_frame>1</use_parent_model_frame>
      </axis>
      <physics>
        <ode>
          <implicit_spring_damper>1</implicit_spring_damper>
          <cfm_damping>1</cfm_damping>
          <limit>
            <cfm>0</cfm>
            <erp>0.2</erp>
          </limit>
        </ode>
      </physics>
    </joint>
    <xacro:SimpleTransmission n="30" joint="RShoulderRoll"/>
    <link name='RElbow'>
      <pose>0.105 -0.113 0.1 0 -0 0</pose>
      <inertial>
        <pose>-0.02744 0 -0.00014 0 -0 0</pose>
        
        <mass value="0.06483"/>        
        <inertia
          ixx="5.59715e-06"
          ixy="4.21e-09"
          ixz="4.319e-08"
          iyy="7.54331e-05"
          iyz="-1.84e-09"
          izz="7.64434e-05"
        />
      </inertial>
      <gravity>1</gravity>
      <velocity_decay/>
      <self_collide>0</self_collide>
    </link>
    <joint name='RElbowYaw' type='revolute'>
      <child>RElbow</child>
      <parent>RBicep</parent>
      <axis>
        <xyz>1 0 0</xyz>
        <limit>
          <lower>-2.08567</lower>
          <upper>2.08567</upper>
          <effort>40.25</effort>
          <velocity>8.26797</velocity>
        </limit>
        <dynamics>
          <damping>0.1</damping>
          <friction>0</friction>
          <spring_reference>0</spring_reference>
          <spring_stiffness>0</spring_stiffness>
        </dynamics>
        <use_parent_model_frame>1</use_parent_model_frame>
      </axis>
      <physics>
        <ode>
          <implicit_spring_damper>1</implicit_spring_damper>
          <cfm_damping>1</cfm_damping>
          <limit>
            <cfm>0</cfm>
            <erp>0.2</erp>
          </limit>
        </ode>
      </physics>
    </joint>
    <xacro:SimpleTransmission n="31" joint="RElbowYaw"/>
    <link name='RForeArm'>
      <pose>0.105 -0.113 0.1 0 -0 0</pose>
      <inertial>
        <pose>0.02556 -0.00281 0.00076 0 -0 0</pose>
        
        <mass value="0.07761"/>        
        <inertia
          ixx="2.53907e-05"
          ixy="2.33243e-06"
          ixz="-6.0117e-07"
          iyy="8.92204e-05"
          iyz="2.694e-08"
          izz="8.72484e-05"
        />
      </inertial>
      <collision name='RForeArm_collision'>
        <pose>0.025325 0 0 1.57 -0 1.57</pose>
        <geometry>
          <cylinder length="0.05065" radius="0.02"/>          
        </geometry>
        <surface>
          <contact>
            <ode/>
          </contact>
          <friction>
            <ode>
              <mu>0.5</mu>
              <mu2>0.5</mu2>
            </ode>
          </friction>
        </surface>
      </collision>
      <visual name='RForeArm_visual'>
        <pose>0 0 0 0 -0 0</pose>
        <geometry>
          <mesh filename="package://robocup_description/nao_red/meshes/V40/RElbowRoll.dae" scale="0.1 0.1 0.1"/>          
        </geometry>
      </visual>
      <gravity>1</gravity>
      <velocity_decay/>
      <self_collide>0</self_collide>
    </link>
    <joint name='RElbowRoll' type='revolute'>
      <child>RForeArm</child>
      <parent>RElbow</parent>
      <axis>
        <xyz>0 0 1</xyz>
        <limit>
          <lower>0.0349066</lower>
          <upper>1.54462</upper>
          <effort>40.25</effort>
          <velocity>7.19407</velocity>
        </limit>
        <dynamics>
          <damping>0.1</damping>
          <friction>0</friction>
          <spring_reference>0</spring_reference>
          <spring_stiffness>0</spring_stiffness>
        </dynamics>
        <use_parent_model_frame>1</use_parent_model_frame>
      </axis>
      <physics>
        <ode>
          <implicit_spring_damper>1</implicit_spring_damper>
          <cfm_damping>1</cfm_damping>
          <limit>
            <cfm>0</cfm>
            <erp>0.2</erp>
          </limit>
        </ode>
      </physics>
    </joint>
    <xacro:SimpleTransmission n="32" joint="RElbowRoll"/>
    <link name='RWrist'>
      <pose>0.16095 -0.113 0.1 0 -0 0</pose>
      <inertial>
        <pose>0.03434 0.00088 0.00308 0 -0 0</pose>
        
        <mass value="0.18533"/>        
        <inertia
          ixx="7.05493e-05"
          ixy="5.71599e-06"
          ixz="-2.24744e-05"
          iyy="0.000356062"
          iyz="3.17771e-06"
          izz="0.000351919"
        />
      </inertial>
      <collision name='RWrist_collision'>
        <pose>0.039 0 0 1.27 -0 1.57</pose>
        <geometry>
          <box size="0.06 0.04 0.058"/>          
        </geometry>
        <surface>
          <contact>
            <ode/>
          </contact>
          <friction>
            <ode>
              <mu>0.5</mu>
              <mu2>0.5</mu2>
            </ode>
          </friction>
        </surface>
      </collision>
      <visual name='RWrist_visual'>
        <pose>0 0 0 0 -0 0</pose>
        <geometry>
          <mesh filename="package://robocup_description/nao_red/meshes/V40/RWristYaw.dae" scale="0.1 0.1 0.1"/>          
        </geometry>
      </visual>
      <gravity>1</gravity>
      <velocity_decay/>
      <self_collide>0</self_collide>
    </link>
    <joint name='RWristYaw' type='revolute'>
      <child>RWrist</child>
      <parent>RForeArm</parent>
      <axis>
        <xyz>1 0 0</xyz>
        <limit>
          <lower>-1.82387</lower>
          <upper>1.82387</upper>
          <effort>40.25</effort>
          <velocity>24.6229</velocity>
        </limit>
        <dynamics>
          <damping>0.1</damping>
          <friction>0</friction>
          <spring_reference>0</spring_reference>
          <spring_stiffness>0</spring_stiffness>
        </dynamics>
        <use_parent_model_frame>1</use_parent_model_frame>
      </axis>
      <physics>
        <ode>
          <implicit_spring_damper>1</implicit_spring_damper>
          <cfm_damping>1</cfm_damping>
          <limit>
            <cfm>0</cfm>
            <erp>0.2</erp>
          </limit>
        </ode>
      </physics>
    </joint>
    <xacro:SimpleTransmission n="33" joint="RWristYaw"/>
    <link name='RFinger11'>
      <pose>0.23002 -0.10143 0.09696 0 -0 0</pose>
      <inertial>
        <pose>0 0 0 0 -0 0</pose>
        
        <mass value="2e-06"/>        
        <inertia
          ixx="1e-09"
          ixy="0"
          ixz="0"
          iyy="1e-09"
          iyz="0"
          izz="1e-09"
        />
      </inertial>
      <visual name='RFinger11_visual'>
        <pose>0 0 0 0 -0 0</pose>
        <geometry>
          <mesh filename="package://robocup_description/nao_red/meshes/V40/RFinger11.dae" scale="0.1 0.1 0.1"/>          
        </geometry>
      </visual>
      <gravity>0</gravity>
      <velocity_decay/>
      <self_collide>0</self_collide>
    </link>
    <joint name='RFinger1' type='revolute'>
      <child>RFinger11</child>
      <parent>RWrist</parent>
      <axis>
        <xyz>0 1 0</xyz>
        <limit>
          <lower>0</lower>
          <upper>0.785398</upper>
          <effort>10</effort>
          <velocity>3</velocity>
        </limit>
        <dynamics>
          <damping>0.1</damping>
          <friction>0</friction>
          <spring_reference>0</spring_reference>
          <spring_stiffness>0</spring_stiffness>
        </dynamics>
        <use_parent_model_frame>1</use_parent_model_frame>
      </axis>
      <physics>
        <ode>
          <implicit_spring_damper>1</implicit_spring_damper>
          <cfm_damping>1</cfm_damping>
          <limit>
            <cfm>0</cfm>
            <erp>0.2</erp>
          </limit>
        </ode>
      </physics>
    </joint>
    <xacro:SimpleTransmission n="34" joint="RFinger1"/>
    <link name='RFinger12'>
      <pose>0.24438 -0.10143 0.09696 0 -0 0</pose>
      <inertial>
        <pose>0 0 0 0 -0 0</pose>
        <mass value="2e-06"/>        
        <inertia
          ixx="1e-09"
          ixy="0"
          ixz="0"
          iyy="1e-09"
          iyz="0"
          izz="1e-09"
        />
      </inertial>
      <visual name='RFinger12_visual'>
        <pose>0 0 0 0 -0 0</pose>
        <geometry>
          <mesh filename="package://robocup_description/nao_red/meshes/V40/RFinger12.dae" scale="0.1 0.1 0.1"/>          
        </geometry>
      </visual>
      <gravity>0</gravity>
      <velocity_decay/>
      <self_collide>0</self_collide>
    </link>
    <joint name='RFinger1_1' type='revolute'>
      <child>RFinger12</child>
      <parent>RFinger11</parent>
      <axis>
        <xyz>0 1 0</xyz>
        <limit>
          <lower>0</lower>
          <upper>0.785398</upper>
          <effort>10</effort>
          <velocity>3</velocity>
        </limit>
        <dynamics>
          <damping>0.1</damping>
          <friction>0</friction>
          <spring_reference>0</spring_reference>
          <spring_stiffness>0</spring_stiffness>
        </dynamics>
        <use_parent_model_frame>1</use_parent_model_frame>
      </axis>
      <physics>
        <ode>
          <implicit_spring_damper>1</implicit_spring_damper>
          <cfm_damping>1</cfm_damping>
          <limit>
            <cfm>0</cfm>
            <erp>0.2</erp>
          </limit>
        </ode>
      </physics>
    </joint>
    <xacro:SimpleTransmission n="35" joint="RFinger1_1"/>
    <link name='RFinger13'>
      <pose>0.25874 -0.10143 0.09696 0 -0 0</pose>
      <inertial>
        <pose>0 0 0 0 -0 0</pose>
        <mass value="2e-06"/>        
        <inertia
          ixx="1e-09"
          ixy="0"
          ixz="0"
          iyy="1e-09"
          iyz="0"
          izz="1e-09"
        />
      </inertial>
      <visual name='RFinger13_visual'>
        <pose>0 0 0 0 -0 0</pose>
        <geometry>
          <mesh filename="package://robocup_description/nao_red/meshes/V40/RFinger13.dae" scale="0.1 0.1 0.1"/>          
        </geometry>
      </visual>
      <gravity>0</gravity>
      <velocity_decay/>
      <self_collide>0</self_collide>
    </link>
    <joint name='RFinger1_2' type='revolute'>
      <child>RFinger13</child>
      <parent>RFinger12</parent>
      <axis>
        <xyz>0 1 0</xyz>
        <limit>
          <lower>0</lower>
          <upper>0.785398</upper>
          <effort>10</effort>
          <velocity>3</velocity>
        </limit>
        <dynamics>
          <damping>0.1</damping>
          <friction>0</friction>
          <spring_reference>0</spring_reference>
          <spring_stiffness>0</spring_stiffness>
        </dynamics>
        <use_parent_model_frame>1</use_parent_model_frame>
      </axis>
      <physics>
        <ode>
          <implicit_spring_damper>1</implicit_spring_damper>
          <cfm_damping>1</cfm_damping>
          <limit>
            <cfm>0</cfm>
            <erp>0.2</erp>
          </limit>
        </ode>
      </physics>
    </joint>
    <xacro:SimpleTransmission n="36" joint="RFinger1_2"/>
    <link name='RFinger21'>
      <pose>0.23002 -0.12457 0.09696 0 -0 0</pose>
      <inertial>
        <pose>0 0 0 0 -0 0</pose>
        <mass value="2e-06"/>        
        <inertia
          ixx="1e-09"
          ixy="0"
          ixz="0"
          iyy="1e-09"
          iyz="0"
          izz="1e-09"
        />
      </inertial>
      <visual name='RFinger21_visual'>
        <pose>0 0 0 0 -0 0</pose>
        <geometry>
          <mesh filename="package://robocup_description/nao_red/meshes/V40/RFinger21.dae" scale="0.1 0.1 0.1"/>          
        </geometry>
      </visual>
      <gravity>0</gravity>
      <velocity_decay/>
      <self_collide>0</self_collide>
    </link>
    <joint name='RFinger2' type='revolute'>
      <child>RFinger21</child>
      <parent>RWrist</parent>
      <axis>
        <xyz>0 1 0</xyz>
        <limit>
          <lower>0</lower>
          <upper>0.785398</upper>
          <effort>10</effort>
          <velocity>3</velocity>
        </limit>
        <dynamics>
          <damping>0.1</damping>
          <friction>0</friction>
          <spring_reference>0</spring_reference>
          <spring_stiffness>0</spring_stiffness>
        </dynamics>
        <use_parent_model_frame>1</use_parent_model_frame>
      </axis>
      <physics>
        <ode>
          <implicit_spring_damper>1</implicit_spring_damper>
          <cfm_damping>1</cfm_damping>
          <limit>
            <cfm>0</cfm>
            <erp>0.2</erp>
          </limit>
        </ode>
      </physics>
    </joint>
    <xacro:SimpleTransmission n="37" joint="RFinger2"/>
    <link name='RFinger22'>
      <pose>0.24438 -0.12457 0.09696 0 -0 0</pose>
      <inertial>
        <pose>0 0 0 0 -0 0</pose>
        <mass value="2e-06"/>        
        <inertia
          ixx="1e-09"
          ixy="0"
          ixz="0"
          iyy="1e-09"
          iyz="0"
          izz="1e-09"
        />
      </inertial>
      <visual name='RFinger22_visual'>
        <pose>0 0 0 0 -0 0</pose>
        <geometry>
          <mesh filename="package://robocup_description/nao_red/meshes/V40/RFinger22.dae" scale="0.1 0.1 0.1"/>          
        </geometry>
      </visual>
      <gravity>0</gravity>
      <velocity_decay/>
      <self_collide>0</self_collide>
    </link>
    <joint name='RFinger2_1' type='revolute'>
      <child>RFinger22</child>
      <parent>RFinger21</parent>
      <axis>
        <xyz>0 1 0</xyz>
        <limit>
          <lower>0</lower>
          <upper>0.785398</upper>
          <effort>10</effort>
          <velocity>3</velocity>
        </limit>
        <dynamics>
          <damping>0.1</damping>
          <friction>0</friction>
          <spring_reference>0</spring_reference>
          <spring_stiffness>0</spring_stiffness>
        </dynamics>
        <use_parent_model_frame>1</use_parent_model_frame>
      </axis>
      <physics>
        <ode>
          <implicit_spring_damper>1</implicit_spring_damper>
          <cfm_damping>1</cfm_damping>
          <limit>
            <cfm>0</cfm>
            <erp>0.2</erp>
          </limit>
        </ode>
      </physics>
    </joint>
    <xacro:SimpleTransmission n="38" joint="RFinger2_1"/>
    <link name='RFinger23'>
      <pose>0.25874 -0.12457 0.09696 0 -0 0</pose>
      <inertial>
        <pose>0 0 0 0 -0 0</pose>
        <mass value="2e-06"/>        
        <inertia
          ixx="1e-09"
          ixy="0"
          ixz="0"
          iyy="1e-09"
          iyz="0"
          izz="1e-09"
        />
      </inertial>
      <visual name='RFinger23_visual'>
        <pose>0 0 0 0 -0 0</pose>
        <geometry>
          <mesh filename="package://robocup_description/nao_red/meshes/V40/RFinger23.dae" scale="0.1 0.1 0.1"/>          
        </geometry>
      </visual>
      <gravity>0</gravity>
      <velocity_decay/>
      <self_collide>0</self_collide>
    </link>
    <joint name='RFinger2_2' type='revolute'>
      <child>RFinger23</child>
      <parent>RFinger22</parent>
      <axis>
        <xyz>0 1 0</xyz>
        <limit>
          <lower>0</lower>
          <upper>0.785398</upper>
          <effort>10</effort>
          <velocity>3</velocity>
        </limit>
        <dynamics>
          <damping>0.1</damping>
          <friction>0</friction>
          <spring_reference>0</spring_reference>
          <spring_stiffness>0</spring_stiffness>
        </dynamics>
        <use_parent_model_frame>1</use_parent_model_frame>
      </axis>
      <physics>
        <ode>
          <implicit_spring_damper>1</implicit_spring_damper>
          <cfm_damping>1</cfm_damping>
          <limit>
            <cfm>0</cfm>
            <erp>0.2</erp>
          </limit>
        </ode>
      </physics>
    </joint>
    <xacro:SimpleTransmission n="39" joint="RFinger2_2"/>
    <link name='RGripper'>
      <pose>0.2187 -0.113 0.08769 0 -0 0</pose>
      <inertial>
        <pose>0 0 0 0 -0 0</pose>
        <mass value="2e-06"/>        
        <inertia
          ixx="1.1e-09"
          ixy="0"
          ixz="0"
          iyy="1.1e-09"
          iyz="0"
          izz="1.1e-09"
        />
      </inertial>
      <gravity>0</gravity>
      <velocity_decay/>
      <self_collide>0</self_collide>
    </link>
    <joint name='RHand' type='revolute'>
      <child>RGripper</child>
      <parent>RWrist</parent>
      <axis>
        <xyz>1 0 0</xyz>
        <limit>
          <lower>0</lower>
          <upper>1</upper>
          <effort>0.177576</effort>
          <velocity>3</velocity>
        </limit>
        <dynamics>
          <damping>0.1</damping>
          <friction>0</friction>
          <spring_reference>0</spring_reference>
          <spring_stiffness>0</spring_stiffness>
        </dynamics>
        <use_parent_model_frame>1</use_parent_model_frame>
      </axis>
      <physics>
        <ode>
          <implicit_spring_damper>1</implicit_spring_damper>
          <cfm_damping>1</cfm_damping>
          <limit>
            <cfm>0</cfm>
            <erp>0.2</erp>
          </limit>
        </ode>
      </physics>
    </joint>
    <xacro:SimpleTransmission n="40" joint="RHand"/>
    <link name='RThumb1'>
      <pose>0.2099 -0.113 0.07362 -3.14159 0.785398 0</pose>
      <inertial>
        <pose>0 0 0 0 -0 0</pose>
        <mass value="2e-06"/>        
        <inertia
          ixx="1e-09"
          ixy="0"
          ixz="0"
          iyy="1e-09"
          iyz="0"
          izz="1e-09"
        />
      </inertial>
      <visual name='RThumb1_visual'>
        <pose>0 0 0 0 -0 0</pose>
        <geometry>
          <mesh filename="package://robocup_description/nao_red/meshes/V40/RThumb1.dae" scale="0.1 0.1 0.1"/>          
        </geometry>
      </visual>
      <gravity>0</gravity>
      <velocity_decay/>
      <self_collide>0</self_collide>
    </link>
    <joint name='RThumb1_joint' type='revolute'>
      <child>RThumb1</child>
      <parent>RWrist</parent>
      <axis>
        <xyz>-0 -1 -0</xyz>
        <limit>
          <lower>0</lower>
          <upper>0.785398</upper>
          <effort>10</effort>
          <velocity>3</velocity>
        </limit>
        <dynamics>
          <damping>0.1</damping>
          <friction>0</friction>
          <spring_reference>0</spring_reference>
          <spring_stiffness>0</spring_stiffness>
        </dynamics>
        <use_parent_model_frame>1</use_parent_model_frame>
      </axis>
      <physics>
        <ode>
          <implicit_spring_damper>1</implicit_spring_damper>
          <cfm_damping>1</cfm_damping>
          <limit>
            <cfm>0</cfm>
            <erp>0.2</erp>
          </limit>
        </ode>
      </physics>
    </joint>
    <xacro:SimpleTransmission n="41" joint="RThumb1_joint"/>
    <link name='RThumb2'>
      <pose>0.220054 -0.113 0.063466 -3.14159 0.785398 0</pose>
      <inertial>
        <pose>0 0 0 0 -0 0</pose>
        <mass value="2e-06"/>        
        <inertia
          ixx="1e-09"
          ixy="0"
          ixz="0"
          iyy="1e-09"
          iyz="0"
          izz="1e-09"
        />
      </inertial>
      <visual name='RThumb2_visual'>
        <pose>0 0 0 0 -0 0</pose>
        <geometry>
          <mesh filename="package://robocup_description/nao_red/meshes/V40/RThumb2.dae" scale="0.1 0.1 0.1"/>          
        </geometry>
      </visual>
      <gravity>0</gravity>
      <velocity_decay/>
      <self_collide>0</self_collide>
    </link>
    <joint name='RThumb1_2' type='revolute'>
      <child>RThumb2</child>
      <parent>RThumb1</parent>
      <axis>
        <xyz>-0 -1 -0</xyz>
        <limit>
          <lower>0</lower>
          <upper>0.785398</upper>
          <effort>10</effort>
          <velocity>3</velocity>
        </limit>
        <dynamics>
          <damping>0.1</damping>
          <friction>0</friction>
          <spring_reference>0</spring_reference>
          <spring_stiffness>0</spring_stiffness>
        </dynamics>
        <use_parent_model_frame>1</use_parent_model_frame>
      </axis>
      <physics>
        <ode>
          <implicit_spring_damper>1</implicit_spring_damper>
          <cfm_damping>1</cfm_damping>
          <limit>
            <cfm>0</cfm>
            <erp>0.2</erp>
          </limit>
        </ode>
      </physics>
    </joint>
    <xacro:SimpleTransmission n="42" joint="RThumb1_2"/>
    
</robot>